Workbook

Sheet Config_Indicadores
A1: Metodologia de Priorização de Setores — Configuração de Indicadores
A3: ID | B3: Eixo | C3: Nome do Indicador | D3: Fonte | E3: Direção | F3: Tipo | G3: Peso | H3: Ativo (S/N) | I3: Observações
A4: IND01 | B4: Econômico | C4: Emprego formal por CNAE na Bahia | D4: Novo CAGED / RAIS | E4: Maior = maior prioridade | F4: Contínuo | G4: 2 | H4: S
A5: IND02 | B5: Econômico | C5: Número de estabelecimentos | D5: Novo CAGED / RAIS | E5: Maior = maior prioridade | F5: Contínuo | G5: 1 | H5: S
A6: IND03 | B6: Econômico | C6: Complexidade Econômica do setor (ICE) | D6: ICE / CEDEPLAR | E6: Maior = maior prioridade | F6: Contínuo | G6: 1 | H6: S
A7: AMB01 | B7: Ambiental | C7: Setor consta na Taxonomia Sustentável Brasileira (TSB)? | D7: TSB / Ministério da Fazenda | E7: Maior = maior prioridade | F7: Binário (0/1) | G7: 1 | H7: S | I7: 0 = Não, 1 = Sim. Já normalizado por natureza, sem min-max
A8: GST01 | B8: Gestão | C8: Setor é prioritário na Nova Indústria Brasil (NIB)? | D8: NIB / MDIC | E8: Maior = maior prioridade | F8: Binário (0/1) | G8: 1 | H8: S | I8: 0 = Não, 1 = Sim. Já normalizado por natureza, sem min-max
A9: GST02 | B9: Gestão | C9: Dependência externa (% valor de fornecedores de fora da BA / valor total do setor) | D9: SIMPAS (UF do fornecedor) | E9: Maior = maior prioridade | F9: Contínuo | G9: 1 | H9: S | I9: Versão adaptada do antigo indicador de dependência externa, agora no Eixo Gestão
A11: Soma dos pesos ativos (denominador da fórmula de score): | G11: {=SUMPRODUCT($G$4:$G$9,--($H$4:$H$9="S"))} -> 7
A13: Nota: o Eixo Social (ex.: % de fornecedores ME/EPP) foi removido temporariamente desta versão da metodologia. Para reincorporá-lo, adicione uma linha SOC0x nesta tabela e a coluna correspondente nas abas Dados_Brutos e Score_Priorizacao.

Sheet Base_dados
A1: Dados por Setor (CNAE) - BAHIA
A2: 2025
A4: CNAE | B4: Setor | C4: IND01 Emprego | D4: IND02 Número de estabelecimentos (un.) | E4: IND03 Complexidade Econômica | F4: AMB01 TSB (0/1) | G4: GST01 NIB (0/1) | H4: GST02 Dependência (%)
A5: 014 | B5: Produção de sementes e mudas certificadas | C5: =VLOOKUP(Tabela1[[#This Row],[CNAE]],'RAIS Vínculos - Bahia 2023-2025'!A:E,3,FALSE) -> 1795 | D5: =VLOOKUP(Tabela1[[#This Row],[CNAE]],'RAIS Estabelecimentos - Bah (2)'!A:E,3,FALSE) -> 102 | E5: =VLOOKUP(Tabela1[[#This Row],[CNAE]],Complexidade!A:D,4,FALSE) -> -1.0904121 | F5: =VLOOKUP(Tabela1[[#This Row],[CNAE]],CNAE_TSB!A:C,3,FALSE) -> 0 | G5: =VLOOKUP(Tabela1[[#This Row],[CNAE]],CNAE_GST!A:C,3,FALSE) -> 0 | H5: =VLOOKUP(Tabela1[[#This Row],[CNAE]],Dependencia_CNAE!A:G,7,FALSE) -> 0
A6: 015 | B6: Pecuária | C6: =VLOOKUP(Tabela1[[#This Row],[CNAE]],'RAIS Vínculos - Bahia 2023-2025'!A:E,3,FALSE) -> 27775 | D6: =VLOOKUP(Tabela1[[#This Row],[CNAE]],'RAIS Estabelecimentos - Bah (2)'!A:E,3,FALSE) -> 8367 | E6: =VLOOKUP(Tabela1[[#This Row],[CNAE]],Complexidade!A:D,4,FALSE) -> -1.8588591 | F6: =VLOOKUP(Tabela1[[#This Row],[CNAE]],CNAE_TSB!A:C,3,FALSE) -> 1 | G6: =VLOOKUP(Tabela1[[#This Row],[CNAE]],CNAE_GST!A:C,3,FALSE) -> 0 | H6: =VLOOKUP(Tabela1[[#This Row],[CNAE]],Dependencia_CNAE!A:G,7,FALSE) -> 0
A7: 089 | B7: Extração de outros minerais não-metálicos | C7: =VLOOKUP(Tabela1[[#This Row],[CNAE]],'RAIS Vínculos - Bahia 2023-2025'!A:E,3,FALSE) -> 2.526 | D7: =VLOOKUP(Tabela1[[#This Row],[CNAE]],'RAIS Estabelecimentos - Bah (2)'!A:E,3,FALSE) -> 77 | E7: =VLOOKUP(Tabela1[[#This Row],[CNAE]],Complexidade!A:D,4,FALSE) -> -1.4621465 | F7: =VLOOKUP(Tabela1[[#This Row],[CNAE]],CNAE_TSB!A:C,3,FALSE) -> 1 | G7: =VLOOKUP(Tabela1[[#This Row],[CNAE]],CNAE_GST!A:C,3,FALSE) -> 0 | H7: =VLOOKUP(Tabela1[[#This Row],[CNAE]],Dependencia_CNAE!A:G,7,FALSE) -> 100
A8: 101 | B8: Abate e fabricação de produtos de carne | C8: =VLOOKUP(Tabela1[[#This Row],[CNAE]],'RAIS Vínculos - Bahia 2023-2025'!A:E,3,FALSE) -> 13.690 | D8: =VLOOKUP(Tabela1[[#This Row],[CNAE]],'RAIS Estabelecimentos - Bah (2)'!A:E,3,FALSE) -> 140 | E8: =VLOOKUP(Tabela1[[#This Row],[CNAE]],Complexidade!A:D,4,FALSE) -> -0.48171224 | F8: =VLOOKUP(Tabela1[[#This Row],[CNAE]],CNAE_TSB!A:C,3,FALSE) -> 0 | G8: =VLOOKUP(Tabela1[[#This Row],[CNAE]],CNAE_GST!A:C,3,FALSE) -> 0 | H8: =VLOOKUP(Tabela1[[#This Row],[CNAE]],Dependencia_CNAE!A:G,7,FALSE) -> 0
A9: 103 | B9: Fabricação de conservas de frutas, legumes e outros vegetais | C9: =VLOOKUP(Tabela1[[#This Row],[CNAE]],'RAIS Vínculos - Bahia 2023-2025'!A:E,3,FALSE) -> 3.227 | D9: =VLOOKUP(Tabela1[[#This Row],[CNAE]],'RAIS Estabelecimentos - Bah (2)'!A:E,3,FALSE) -> 220 | E9: =VLOOKUP(Tabela1[[#This Row],[CNAE]],Complexidade!A:D,4,FALSE) -> -0.91636945 | F9: =VLOOKUP(Tabela1[[#This Row],[CNAE]],CNAE_TSB!A:C,3,FALSE) -> 0 | G9: =VLOOKUP(Tabela1[[#This Row],[CNAE]],CNAE_GST!A:C,3,FALSE) -> 0 | H9: =VLOOKUP(Tabela1[[#This Row],[CNAE]],Dependencia_CNAE!A:G,7,FALSE) -> 0
A10: 104 | B10: Fabricação de óleos e gorduras vegetais e animais | C10: =VLOOKUP(Tabela1[[#This Row],[CNAE]],'RAIS Vínculos - Bahia 2023-2025'!A:E,3,FALSE) -> 1.654 | D10: =VLOOKUP(Tabela1[[#This Row],[CNAE]],'RAIS Estabelecimentos - Bah (2)'!A:E,3,FALSE) -> 37 | E10: =VLOOKUP(Tabela1[[#This Row],[CNAE]],Complexidade!A:D,4,FALSE) -> -0.54271957 | F10: =VLOOKUP(Tabela1[[#This Row],[CNAE]],CNAE_TSB!A:C,3,FALSE) -> 0 | G10: =VLOOKUP(Tabela1[[#This Row],[CNAE]],CNAE_GST!A:C,3,FALSE) -> 0 | H10: =VLOOKUP(Tabela1[[#This Row],[CNAE]],Dependencia_CNAE!A:G,7,FALSE) -> 0
A11: 105 | B11: Laticínios | C11: =VLOOKUP(Tabela1[[#This Row],[CNAE]],'RAIS Vínculos - Bahia 2023-2025'!A:E,3,FALSE) -> 5.773 | D11: =VLOOKUP(Tabela1[[#This Row],[CNAE]],'RAIS Estabelecimentos - Bah (2)'!A:E,3,FALSE) -> 410 | E11: =VLOOKUP(Tabela1[[#This Row],[CNAE]],Complexidade!A:D,4,FALSE) -> -1.3002286 | F11: =VLOOKUP(Tabela1[[#This Row],[CNAE]],CNAE_TSB!A:C,3,FALSE) -> 0 | G11: =VLOOKUP(Tabela1[[#This Row],[CNAE]],CNAE_GST!A:C,3,FALSE) -> 0 | H11: =VLOOKUP(Tabela1[[#This Row],[CNAE]],Dependencia_CNAE!A:G,7,FALSE) -> 0.41
A12: 106 | B12: Moagem, fabricação de produtos amiláceos e de alimentos para animais | C12: =VLOOKUP(Tabela1[[#This Row],[CNAE]],'RAIS Vínculos - Bahia 2023-2025'!A:E,3,FALSE) -> 6.609 | D12: =VLOOKUP(Tabela1[[#This Row],[CNAE]],'RAIS Estabelecimentos - Bah (2)'!A:E,3,FALSE) -> 205 | E12: =VLOOKUP(Tabela1[[#This Row],[CNAE]],Complexidade!A:D,4,FALSE) -> -0.86387357 | F12: =VLOOKUP(Tabela1[[#This Row],[CNAE]],CNAE_TSB!A:C,3,FALSE) -> 0 | G12: =VLOOKUP(Tabela1[[#This Row],[CNAE]],CNAE_GST!A:C,3,FALSE) -> 0 | H12: =VLOOKUP(Tabela1[[#This Row],[CNAE]],Dependencia_CNAE!A:G,7,FALSE) -> 1.29
A13: 107 | B13: Fabricação e refino de açúcar | C13: =VLOOKUP(Tabela1[[#This Row],[CNAE]],'RAIS Vínculos - Bahia 2023-2025'!A:E,3,FALSE) -> 3.002 | D13: =VLOOKUP(Tabela1[[#This Row],[CNAE]],'RAIS Estabelecimentos - Bah (2)'!A:E,3,FALSE) -> 6 | E13: =VLOOKUP(Tabela1[[#This Row],[CNAE]],Complexidade!A:D,4,FALSE) -> -0.57520505 | F13: =VLOOKUP(Tabela1[[#This Row],[CNAE]],CNAE_TSB!A:C,3,FALSE) -> 0 | G13: =VLOOKUP(Tabela1[[#This Row],[CNAE]],CNAE_GST!A:C,3,FALSE) -> 0 | H13: =VLOOKUP(Tabela1[[#This Row],[CNAE]],Dependencia_CNAE!A:G,7,FALSE) -> 0
A14: 109 | B14: Fabricação de outros produtos alimentícios | C14: =VLOOKUP(Tabela1[[#This Row],[CNAE]],'RAIS Vínculos - Bahia 2023-2025'!A:E,3,FALSE) -> 20.366 | D14: =VLOOKUP(Tabela1[[#This Row],[CNAE]],'RAIS Estabelecimentos - Bah (2)'!A:E,3,FALSE) -> 2.107 | E14: =VLOOKUP(Tabela1[[#This Row],[CNAE]],Complexidade!A:D,4,FALSE) -> -0.60201064 | F14: =VLOOKUP(Tabela1[[#This Row],[CNAE]],CNAE_TSB!A:C,3,FALSE) -> 0 | G14: =VLOOKUP(Tabela1[[#This Row],[CNAE]],CNAE_GST!A:C,3,FALSE) -> 0 | H14: =VLOOKUP(Tabela1[[#This Row],[CNAE]],Dependencia_CNAE!A:G,7,FALSE) -> 48.06
A15: 111 | B15: Fabricação de bebidas alcoólicas | C15: =VLOOKUP(Tabela1[[#This Row],[CNAE]],'RAIS Vínculos - Bahia 2023-2025'!A:E,3,FALSE) -> 2.967 | D15: =VLOOKUP(Tabela1[[#This Row],[CNAE]],'RAIS Estabelecimentos - Bah (2)'!A:E,3,FALSE) -> 65 | E15: =VLOOKUP(Tabela1[[#This Row],[CNAE]],Complexidade!A:D,4,FALSE) -> -0.70675988 | F15: =VLOOKUP(Tabela1[[#This Row],[CNAE]],CNAE_TSB!A:C,3,FALSE) -> 0 | G15: =VLOOKUP(Tabela1[[#This Row],[CNAE]],CNAE_GST!A:C,3,FALSE) -> 0 | H15: =VLOOKUP(Tabela1[[#This Row],[CNAE]],Dependencia_CNAE!A:G,7,FALSE) -> 0
A16: 112 | B16: Fabricação de bebidas não-alcoólicas | C16: =VLOOKUP(Tabela1[[#This Row],[CNAE]],'RAIS Vínculos - Bahia 2023-2025'!A:E,3,FALSE) -> 4.350 | D16: =VLOOKUP(Tabela1[[#This Row],[CNAE]],'RAIS Estabelecimentos - Bah (2)'!A:E,3,FALSE) -> 60 | E16: =VLOOKUP(Tabela1[[#This Row],[CNAE]],Complexidade!A:D,4,FALSE) -> -0.67218226 | F16: =VLOOKUP(Tabela1[[#This Row],[CNAE]],CNAE_TSB!A:C,3,FALSE) -> 0 | G16: =VLOOKUP(Tabela1[[#This Row],[CNAE]],CNAE_GST!A:C,3,FALSE) -> 0 | H16: =VLOOKUP(Tabela1[[#This Row],[CNAE]],Dependencia_CNAE!A:G,7,FALSE) -> 2.07
... A87: 620 | B87: Atividades dos serviços de tecnologia da informação | C87: =VLOOKUP(Tabela1[[#This Row],[CNAE]],'RAIS Vínculos - Bahia 2023-2025'!A:E,3,FALSE) -> 11463 | D87: =VLOOKUP(Tabela1[[#This Row],[CNAE]],'RAIS Estabelecimentos - Bah (2)'!A:E,3,FALSE) -> 715 | E87: =VLOOKUP(Tabela1[[#This Row],[CNAE]],Complexidade!A:D,4,FALSE) -> 0.099233406 | F87: =VLOOKUP(Tabela1[[#This Row],[CNAE]],CNAE_TSB!A:C,3,FALSE) -> 0 | G87: =VLOOKUP(Tabela1[[#This Row],[CNAE]],CNAE_GST!A:C,3,FALSE) -> 1 | H87: =VLOOKUP(Tabela1[[#This Row],[CNAE]],Dependencia_CNAE!A:G,7,FALSE) -> 10.48

Sheet Score_Priorizacao
A1: Score de Priorização por Setor
K3: =MEDIAN(Tabela4[Tx Variação]) -> 1.53 | L3: =MEDIAN(Tabela4[Volume compra 2025]) -> 3766643.9
A4: CNAE | B4: Setor | C4: IND01 (norm.) | D4: IND02 (norm.) | E4: IND03 (norm.) | F4: AMB01 (norm.) | G4: GST01 (norm.) | H4: GST02 (norm.) | I4: Score Final | J4: Ranking | K4: Tx Variação | L4: Volume compra 2025 | M4: Class Tx | N4: Class Volume | O4: Classificação geral
A5: 212 | B5: Fabricação de produtos farmacêuticos | C5: =(VLOOKUP($A5,Base_dados!$A$5:$H$103,3,FALSE())-MIN(Tabela1[IND01 Emprego]))/(MAX(Tabela1[IND01 Emprego])-MIN(Tabela1[IND01 Emprego])) -> 0.044320432 | D5: =(VLOOKUP($A5,Base_dados!$A$5:$H$103,4,FALSE())-MIN(Base_dados!C$5:C$103))/(MAX(Base_dados!C$5:C$103)-MIN(Base_dados!C$5:C$103)) -> 0.0002160216 | E5: =(VLOOKUP($A5,Base_dados!$A$5:$H$103,5,FALSE())-MIN(Tabela1[IND03 Complexidade Econômica]))/(MAX(Tabela1[IND03 Complexidade Econômica])-MIN(Tabela1[IND03 Complexidade Econômica])) -> 0.83164081 | F5: =VLOOKUP($A5,Base_dados!A:H,6,FALSE()) -> 0 | G5: =VLOOKUP($A5,Base_dados!$A$5:$H$103,7,FALSE()) -> 1 | H5: =(VLOOKUP(Tabela4[[#This Row],[CNAE]],Tabela1[],8,FALSE))/100 -> 0.7942 | I5: =(C5*Config_Indicadores!$G$4+D5*Config_Indicadores!$G$5+E5*Config_Indicadores!$G$6+F5*Config_Indicadores!$G$7+G5*Config_Indicadores!$G$7+H5*Config_Indicadores!$G$8)/Config_Indicadores!$G$11 -> 0.38781396 | J5: =RANK(I5,Tabela4[Score Final],0) -> 7 | K5: =VLOOKUP(Tabela4[[#This Row],[CNAE]],Síntese2!A:G,6,FALSE) -> 50.69 | L5: =VLOOKUP(Tabela4[[#This Row],[CNAE]],Síntese2!A:G,3,FALSE) -> 8.8607514e+08 | M5: =IF(Tabela4[[#This Row],[Tx Variação]]>=MEDIAN(Tabela4[Tx Variação]), "Alto","Baixo") -> Alto | N5: =IF(Tabela4[[#This Row],[Volume compra 2025]]>=MEDIAN(Tabela4[Volume compra 2025]), "Alto","Baixo") -> Alto | O5: =IF(AND(Tabela4[[#This Row],[Class Tx]]="Alto",Tabela4[[#This Row],[Class Volume]]="Alto"),"Estratégico",IF(AND(Tabela4[[#This Row],[Class Tx]]="Alto",Tabela4[[#This Row],[Class Volume]]="Baixo"),"Alavancagem",IF(AND(Tabela4[[#This Row],[Class Tx]]="Baixo",Tabela4[[#This Row],[Class Volume]]="Baixo"),"Não Crítico","Gargalo"))) -> Estratégico
A6: 291 | B6: Fabricação de automóveis, camionetas e utilitários | C6: =(VLOOKUP($A6,Base_dados!$A$5:$H$103,3,FALSE())-MIN(Tabela1[IND01 Emprego]))/(MAX(Tabela1[IND01 Emprego])-MIN(Tabela1[IND01 Emprego])) -> 0.075679568 | D6: =(VLOOKUP($A6,Base_dados!$A$5:$H$103,4,FALSE())-MIN(Base_dados!C$5:C$103))/(MAX(Base_dados!C$5:C$103)-MIN(Base_dados!C$5:C$103)) -> 3.60036e-05 | E6: =(VLOOKUP($A6,Base_dados!$A$5:$H$103,5,FALSE())-MIN(Tabela1[IND03 Complexidade Econômica]))/(MAX(Tabela1[IND03 Complexidade Econômica])-MIN(Tabela1[IND03 Complexidade Econômica])) -> 0.94986192 | F6: =VLOOKUP($A6,Base_dados!A:H,6,FALSE()) -> 0 | G6: =VLOOKUP($A6,Base_dados!$A$5:$H$103,7,FALSE()) -> 0 | H6: =(VLOOKUP(Tabela4[[#This Row],[CNAE]],Tabela1[],8,FALSE))/100 -> 0.515 | I6: =(C6*Config_Indicadores!$G$4+D6*Config_Indicadores!$G$5+E6*Config_Indicadores!$G$6+F6*Config_Indicadores!$G$7+G6*Config_Indicadores!$G$7+H6*Config_Indicadores!$G$8)/Config_Indicadores!$G$11 -> 0.23089387 | J6: =RANK(I6,Tabela4[Score Final],0) -> 37 | K6: =VLOOKUP(Tabela4[[#This Row],[CNAE]],Síntese2!A:G,6,FALSE) -> 133.9 | L6: =VLOOKUP(Tabela4[[#This Row],[CNAE]],Síntese2!A:G,3,FALSE) -> 5.0631582e+08 | M6: =IF(Tabela4[[#This Row],[Tx Variação]]>=MEDIAN(Tabela4[Tx Variação]), "Alto","Baixo") -> Alto | N6: =IF(Tabela4[[#This Row],[Volume compra 2025]]>=MEDIAN(Tabela4[Volume compra 2025]), "Alto","Baixo") -> Alto | O6: =IF(AND(Tabela4[[#This Row],[Class Tx]]="Alto",Tabela4[[#This Row],[Class Volume]]="Alto"),"Estratégico",IF(AND(Tabela4[[#This Row],[Class Tx]]="Alto",Tabela4[[#This Row],[Class Volume]]="Baixo"),"Alavancagem",IF(AND(Tabela4[[#This Row],[Class Tx]]="Baixo",Tabela4[[#This Row],[Class Volume]]="Baixo"),"Não Crítico","Gargalo"))) -> Estratégico
A7: 325 | B7: Fabricação de instrumentos e materiais para uso médico e odontológico e de artigos ópticos | C7: =(VLOOKUP($A7,Base_dados!$A$5:$H$103,3,FALSE())-MIN(Tabela1[IND01 Emprego]))/(MAX(Tabela1[IND01 Emprego])-MIN(Tabela1[IND01 Emprego])) -> 0.042952295 | D7: =(VLOOKUP($A7,Base_dados!$A$5:$H$103,4,FALSE())-MIN(Base_dados!C$5:C$103))/(MAX(Base_dados!C$5:C$103)-MIN(Base_dados!C$5:C$103)) -> 0.0068046805 | E7: =(VLOOKUP($A7,Base_dados!$A$5:$H$103,5,FALSE())-MIN(Tabela1[IND03 Complexidade Econômica]))/(MAX(Tabela1[IND03 Complexidade Econômica])-MIN(Tabela1[IND03 Complexidade Econômica])) -> 0.55264622 | F7: =VLOOKUP($A7,Base_dados!A:H,6,FALSE()) -> 0 | G7: =VLOOKUP($A7,Base_dados!$A$5:$H$103,7,FALSE()) -> 1 | H7: =(VLOOKUP(Tabela4[[#This Row],[CNAE]],Tabela1[],8,FALSE))/100 -> 0.6042 | I7: =(C7*Config_Indicadores!$G$4+D7*Config_Indicadores!$G$5+E7*Config_Indicadores!$G$6+F7*Config_Indicadores!$G$7+G7*Config_Indicadores!$G$7+H7*Config_Indicadores!$G$8)/Config_Indicadores!$G$11 -> 0.32136507 | J7: =RANK(I7,Tabela4[Score Final],0) -> 17 | K7: =VLOOKUP(Tabela4[[#This Row],[CNAE]],Síntese2!A:G,6,FALSE) -> -4.24 | L7: =VLOOKUP(Tabela4[[#This Row],[CNAE]],Síntese2!A:G,3,FALSE) -> 3.6724693e+08 | M7: =IF(Tabela4[[#This Row],[Tx Variação]]>=MEDIAN(Tabela4[Tx Variação]), "Alto","Baixo") -> Baixo | N7: =IF(Tabela4[[#This Row],[Volume compra 2025]]>=MEDIAN(Tabela4[Volume compra 2025]), "Alto","Baixo") -> Alto | O7: =IF(AND(Tabela4[[#This Row],[Class Tx]]="Alto",Tabela4[[#This Row],[Class Volume]]="Alto"),"Estratégico",IF(AND(Tabela4[[#This Row],[Class Tx]]="Alto",Tabela4[[#This Row],[Class Volume]]="Baixo"),"Alavancagem",IF(AND(Tabela4[[#This Row],[Class Tx]]="Baixo",Tabela4[[#This Row],[Class Volume]]="Baixo"),"Não Crítico","Gargalo"))) -> Gargalo
A8: 262 | B8: Fabricação de equipamentos de informática e periféricos | C8: =(VLOOKUP($A8,Base_dados!$A$5:$H$103,3,FALSE())-MIN(Tabela1[IND01 Emprego]))/(MAX(Tabela1[IND01 Emprego])-MIN(Tabela1[IND01 Emprego])) -> 0.033123312 | D8: =(VLOOKUP($A8,Base_dados!$A$5:$H$103,4,FALSE())-MIN(Base_dados!C$5:C$103))/(MAX(Base_dados!C$5:C$103)-MIN(Base_dados!C$5:C$103)) -> 0.00079207921 | E8: =(VLOOKUP($A8,Base_dados!$A$5:$H$103,5,FALSE())-MIN(Tabela1[IND03 Complexidade Econômica]))/(MAX(Tabela1[IND03 Complexidade Econômica])-MIN(Tabela1[IND03 Complexidade Econômica])) -> 0.87246241 | F8: =VLOOKUP($A8,Base_dados!A:H,6,FALSE()) -> 0 | G8: =VLOOKUP($A8,Base_dados!$A$5:$H$103,7,FALSE()) -> 0 | H8: =(VLOOKUP(Tabela4[[#This Row],[CNAE]],Tabela1[],8,FALSE))/100 -> 0.1431 | I8: =(C8*Config_Indicadores!$G$4+D8*Config_Indicadores!$G$5+E8*Config_Indicadores!$G$6+F8*Config_Indicadores!$G$7+G8*Config_Indicadores!$G$7+H8*Config_Indicadores!$G$8)/Config_Indicadores!$G$11 -> 0.1546573 | J8: =RANK(I8,Tabela4[Score Final],0) -> 56 | K8: =VLOOKUP(Tabela4[[#This Row],[CNAE]],Síntese2!A:G,6,FALSE) -> 33.28 | L8: =VLOOKUP(Tabela4[[#This Row],[CNAE]],Síntese2!A:G,3,FALSE) -> 1.6621647e+08 | M8: =IF(Tabela4[[#This Row],[Tx Variação]]>=MEDIAN(Tabela4[Tx Variação]), "Alto","Baixo") -> Alto | N8: =IF(Tabela4[[#This Row],[Volume compra 2025]]>=MEDIAN(Tabela4[Volume compra 2025]), "Alto","Baixo") -> Alto | O8: =IF(AND(Tabela4[[#This Row],[Class Tx]]="Alto",Tabela4[[#This Row],[Class Volume]]="Alto"),"Estratégico",IF(AND(Tabela4[[#This Row],[Class Tx]]="Alto",Tabela4[[#This Row],[Class Volume]]="Baixo"),"Alavancagem",IF(AND(Tabela4[[#This Row],[Class Tx]]="Baixo",Tabela4[[#This Row],[Class Volume]]="Baixo"),"Não Crítico","Gargalo"))) -> Estratégico
A9: 283 | B9: Fabricação de tratores e de máquinas e equipamentos para a agricultura e pecuária | C9: =(VLOOKUP($A9,Base_dados!$A$5:$H$103,3,FALSE())-MIN(Tabela1[IND01 Emprego]))/(MAX(Tabela1[IND01 Emprego])-MIN(Tabela1[IND01 Emprego])) -> 0.012133213 | D9: =(VLOOKUP($A9,Base_dados!$A$5:$H$103,4,FALSE())-MIN(Base_dados!C$5:C$103))/(MAX(Base_dados!C$5:C$103)-MIN(Base_dados!C$5:C$103)) -> 0.001260126 | E9: =(VLOOKUP($A9,Base_dados!$A$5:$H$103,5,FALSE())-MIN(Tabela1[IND03 Complexidade Econômica]))/(MAX(Tabela1[IND03 Complexidade Econômica])-MIN(Tabela1[IND03 Complexidade Econômica])) -> 0.47523442 | F9: =VLOOKUP($A9,Base_dados!A:H,6,FALSE()) -> 0 | G9: =VLOOKUP($A9,Base_dados!$A$5:$H$103,7,FALSE()) -> 0 | H9: =(VLOOKUP(Tabela4[[#This Row],[CNAE]],Tabela1[],8,FALSE))/100 -> 0.7236 | I9: =(C9*Config_Indicadores!$G$4+D9*Config_Indicadores!$G$5+E9*Config_Indicadores!$G$6+F9*Config_Indicadores!$G$7+G9*Config_Indicadores!$G$7+H9*Config_Indicadores!$G$8)/Config_Indicadores!$G$11 -> 0.17490871 | J9: =RANK(I9,Tabela4[Score Final],0) -> 54 | K9: =VLOOKUP(Tabela4[[#This Row],[CNAE]],Síntese2!A:G,6,FALSE) -> 42.72 | L9: =VLOOKUP(Tabela4[[#This Row],[CNAE]],Síntese2!A:G,3,FALSE) -> 1.2169332e+08 | M9: =IF(Tabela4[[#This Row],[Tx Variação]]>=MEDIAN(Tabela4[Tx Variação]), "Alto","Baixo") -> Alto | N9: =IF(Tabela4[[#This Row],[Volume compra 2025]]>=MEDIAN(Tabela4[Volume compra 2025]), "Alto","Baixo") -> Alto | O9: =IF(AND(Tabela4[[#This Row],[Class Tx]]="Alto",Tabela4[[#This Row],[Class Volume]]="Alto"),"Estratégico",IF(AND(Tabela4[[#This Row],[Class Tx]]="Alto",Tabela4[[#This Row],[Class Volume]]="Baixo"),"Alavancagem",IF(AND(Tabela4[[#This Row],[Class Tx]]="Baixo",Tabela4[[#This Row],[Class Volume]]="Baixo"),"Não Crítico","Gargalo"))) -> Estratégico
A10: 304 | B10: Fabricação de aeronaves | C10: =(VLOOKUP($A10,Base_dados!$A$5:$H$103,3,FALSE())-MIN(Tabela1[IND01 Emprego]))/(MAX(Tabela1[IND01 Emprego])-MIN(Tabela1[IND01 Emprego])) -> 0 | D10: =(VLOOKUP($A10,Base_dados!$A$5:$H$103,4,FALSE())-MIN(Base_dados!C$5:C$103))/(MAX(Base_dados!C$5:C$103)-MIN(Base_dados!C$5:C$103)) -> 0 | E10: =(VLOOKUP($A10,Base_dados!$A$5:$H$103,5,FALSE())-MIN(Tabela1[IND03 Complexidade Econômica]))/(MAX(Tabela1[IND03 Complexidade Econômica])-MIN(Tabela1[IND03 Complexidade Econômica])) -> 0.80913476 | F10: =VLOOKUP($A10,Base_dados!A:H,6,FALSE()) -> 0 | G10: =VLOOKUP($A10,Base_dados!$A$5:$H$103,7,FALSE()) -> 0 | H10: =(VLOOKUP(Tabela4[[#This Row],[CNAE]],Tabela1[],8,FALSE))/100 -> 0.9993 | I10: =(C10*Config_Indicadores!$G$4+D10*Config_Indicadores!$G$5+E10*Config_Indicadores!$G$6+F10*Config_Indicadores!$G$7+G10*Config_Indicadores!$G$7+H10*Config_Indicadores!$G$8)/Config_Indicadores!$G$11 -> 0.25834782 | J10: =RANK(I10,Tabela4[Score Final],0) -> 27 | K10: =VLOOKUP(Tabela4[[#This Row],[CNAE]],Síntese2!A:G,6,FALSE) -> 7883.18 | L10: =VLOOKUP(Tabela4[[#This Row],[CNAE]],Síntese2!A:G,3,FALSE) -> 1.0857182e+08 | M10: =IF(Tabela4[[#This Row],[Tx Variação]]>=MEDIAN(Tabela4[Tx Variação]), "Alto","Baixo") -> Alto | N10: =IF(Tabela4[[#This Row],[Volume compra 2025]]>=MEDIAN(Tabela4[Volume compra 2025]), "Alto","Baixo") -> Alto | O10: =IF(AND(Tabela4[[#This Row],[Class Tx]]="Alto",Tabela4[[#This Row],[Class Volume]]="Alto"),"Estratégico",IF(AND(Tabela4[[#This Row],[Class Tx]]="Alto",Tabela4[[#This Row],[Class Volume]]="Baixo"),"Alavancagem",IF(AND(Tabela4[[#This Row],[Class Tx]]="Baixo",Tabela4[[#This Row],[Class Volume]]="Baixo"),"Não Crítico","Gargalo"))) -> Estratégico
A11: 292 | B11: Fabricação de caminhões e ônibus | C11: =(VLOOKUP($A11,Base_dados!$A$5:$H$103,3,FALSE())-MIN(Tabela1[IND01 Emprego]))/(MAX(Tabela1[IND01 Emprego])-MIN(Tabela1[IND01 Emprego])) -> 0 | D11: =(VLOOKUP($A11,Base_dados!$A$5:$H$103,4,FALSE())-MIN(Base_dados!C$5:C$103))/(MAX(Base_dados!C$5:C$103)-MIN(Base_dados!C$5:C$103)) -> 0 | E11: =(VLOOKUP($A11,Base_dados!$A$5:$H$103,5,FALSE())-MIN(Tabela1[IND03 Complexidade Econômica]))/(MAX(Tabela1[IND03 Complexidade Econômica])-MIN(Tabela1[IND03 Complexidade Econômica])) -> 1 | F11: =VLOOKUP($A11,Base_dados!A:H,6,FALSE()) -> 0 | G11: =VLOOKUP($A11,Base_dados!$A$5:$H$103,7,FALSE()) -> 0 | H11: =(VLOOKUP(Tabela4[[#This Row],[CNAE]],Tabela1[],8,FALSE))/100 -> 0.7613 | I11: =(C11*Config_Indicadores!$G$4+D11*Config_Indicadores!$G$5+E11*Config_Indicadores!$G$6+F11*Config_Indicadores!$G$7+G11*Config_Indicadores!$G$7+H11*Config_Indicadores!$G$8)/Config_Indicadores!$G$11 -> 0.25161429 | J11: =RANK(I11,Tabela4[Score Final],0) -> 29 | K11: =VLOOKUP(Tabela4[[#This Row],[CNAE]],Síntese2!A:G,6,FALSE) -> 1567.14 | L11: =VLOOKUP(Tabela4[[#This Row],[CNAE]],Síntese2!A:G,3,FALSE) -> 100210843 | M11: =IF(Tabela4[[#This Row],[Tx Variação]]>=MEDIAN(Tabela4[Tx Variação]), "Alto","Baixo") -> Alto | N11: =IF(Tabela4[[#This Row],[Volume compra 2025]]>=MEDIAN(Tabela4[Volume compra 2025]), "Alto","Baixo") -> Alto | O11: =IF(AND(Tabela4[[#This Row],[Class Tx]]="Alto",Tabela4[[#This Row],[Class Volume]]="Alto"),"Estratégico",IF(AND(Tabela4[[#This Row],[Class Tx]]="Alto",Tabela4[[#This Row],[Class Volume]]="Baixo"),"Alavancagem",IF(AND(Tabela4[[#This Row],[Class Tx]]="Baixo",Tabela4[[#This Row],[Class Volume]]="Baixo"),"Não Crítico","Gargalo"))) -> Estratégico
A12: 211 | B12: Fabricação de produtos farmoquímicos | C12: =(VLOOKUP($A12,Base_dados!$A$5:$H$103,3,FALSE())-MIN(Tabela1[IND01 Emprego]))/(MAX(Tabela1[IND01 Emprego])-MIN(Tabela1[IND01 Emprego])) -> 0.00072007201 | D12: =(VLOOKUP($A12,Base_dados!$A$5:$H$103,4,FALSE())-MIN(Base_dados!C$5:C$103))/(MAX(Base_dados!C$5:C$103)-MIN(Base_dados!C$5:C$103)) -> 3.60036e-05 | E12: =(VLOOKUP($A12,Base_dados!$A$5:$H$103,5,FALSE())-MIN(Tabela1[IND03 Complexidade Econômica]))/(MAX(Tabela1[IND03 Complexidade Econômica])-MIN(Tabela1[IND03 Complexidade Econômica])) -> 0.69444381 | F12: =VLOOKUP($A12,Base_dados!A:H,6,FALSE()) -> 0 | G12: =VLOOKUP($A12,Base_dados!$A$5:$H$103,7,FALSE()) -> 1 | H12: =(VLOOKUP(Tabela4[[#This Row],[CNAE]],Tabela1[],8,FALSE))/100 -> 0.6076 | I12: =(C12*Config_Indicadores!$G$4+D12*Config_Indicadores!$G$5+E12*Config_Indicadores!$G$6+F12*Config_Indicadores!$G$7+G12*Config_Indicadores!$G$7+H12*Config_Indicadores!$G$8)/Config_Indicadores!$G$11 -> 0.32907428 | J12: =RANK(I12,Tabela4[Score Final],0) -> 13 | K12: =VLOOKUP(Tabela4[[#This Row],[CNAE]],Síntese2!A:G,6,FALSE) -> 23.74 | L12: =VLOOKUP(Tabela4[[#This Row],[CNAE]],Síntese2!A:G,3,FALSE) -> 77553396 | M12: =IF(Tabela4[[#This Row],[Tx Variação]]>=MEDIAN(Tabela4[Tx Variação]), "Alto","Baixo") -> Alto | N12: =IF(Tabela4[[#This Row],[Volume compra 2025]]>=MEDIAN(Tabela4[Volume compra 2025]), "Alto","Baixo") -> Alto | O12: =IF(AND(Tabela4[[#This Row],[Class Tx]]="Alto",Tabela4[[#This Row],[Class Volume]]="Alto"),"Estratégico",IF(AND(Tabela4[[#This Row],[Class Tx]]="Alto",Tabela4[[#This Row],[Class Volume]]="Baixo"),"Alavancagem",IF(AND(Tabela4[[#This Row],[Class Tx]]="Baixo",Tabela4[[#This Row],[Class Volume]]="Baixo"),"Não Crítico","Gargalo"))) -> Estratégico
A13: 141 | B13: Confecção de artigos do vestuário e acessórios | C13: =(VLOOKUP($A13,Base_dados!$A$5:$H$103,3,FALSE())-MIN(Tabela1[IND01 Emprego]))/(MAX(Tabela1[IND01 Emprego])-MIN(Tabela1[IND01 Emprego])) -> 0.35924392 | D13: =(VLOOKUP($A13,Base_dados!$A$5:$H$103,4,FALSE())-MIN(Base_dados!C$5:C$103))/(MAX(Base_dados!C$5:C$103)-MIN(Base_dados!C$5:C$103)) -> 0.032331233 | E13: =(VLOOKUP($A13,Base_dados!$A$5:$H$103,5,FALSE())-MIN(Tabela1[IND03 Complexidade Econômica]))/(MAX(Tabela1[IND03 Complexidade Econômica])-MIN(Tabela1[IND03 Complexidade Econômica])) -> 0.23843616 | F13: =VLOOKUP($A13,Base_dados!A:H,6,FALSE()) -> 0 | G13: =VLOOKUP($A13,Base_dados!$A$5:$H$103,7,FALSE()) -> 1 | H13: =(VLOOKUP(Tabela4[[#This Row],[CNAE]],Tabela1[],8,FALSE))/100 -> 0.2884 | I13: =(C13*Config_Indicadores!$G$4+D13*Config_Indicadores!$G$5+E13*Config_Indicadores!$G$6+F13*Config_Indicadores!$G$7+G13*Config_Indicadores!$G$7+H13*Config_Indicadores!$G$8)/Config_Indicadores!$G$11 -> 0.32537932 | J13: =RANK(I13,Tabela4[Score Final],0) -> 15 | K13: =VLOOKUP(Tabela4[[#This Row],[CNAE]],Síntese2!A:G,6,FALSE) -> 19.61 | L13: =VLOOKUP(Tabela4[[#This Row],[CNAE]],Síntese2!A:G,3,FALSE) -> 65230981 | M13: =IF(Tabela4[[#This Row],[Tx Variação]]>=MEDIAN(Tabela4[Tx Variação]), "Alto","Baixo") -> Alto | N13: =IF(Tabela4[[#This Row],[Volume compra 2025]]>=MEDIAN(Tabela4[Volume compra 2025]), "Alto","Baixo") -> Alto | O13: =IF(AND(Tabela4[[#This Row],[Class Tx]]="Alto",Tabela4[[#This Row],[Class Volume]]="Alto"),"Estratégico",IF(AND(Tabela4[[#This Row],[Class Tx]]="Alto",Tabela4[[#This Row],[Class Volume]]="Baixo"),"Alavancagem",IF(AND(Tabela4[[#This Row],[Class Tx]]="Baixo",Tabela4[[#This Row],[Class Volume]]="Baixo"),"Não Crítico","Gargalo"))) -> Estratégico
A14: 275 | B14: Fabricação de eletrodomésticos | C14: =(VLOOKUP($A14,Base_dados!$A$5:$H$103,3,FALSE())-MIN(Tabela1[IND01 Emprego]))/(MAX(Tabela1[IND01 Emprego])-MIN(Tabela1[IND01 Emprego])) -> 0.21130513 | D14: =(VLOOKUP($A14,Base_dados!$A$5:$H$103,4,FALSE())-MIN(Base_dados!C$5:C$103))/(MAX(Base_dados!C$5:C$103)-MIN(Base_dados!C$5:C$103)) -> 0.000360036 | E14: =(VLOOKUP($A14,Base_dados!$A$5:$H$103,5,FALSE())-MIN(Tabela1[IND03 Complexidade Econômica]))/(MAX(Tabela1[IND03 Complexidade Econômica])-MIN(Tabela1[IND03 Complexidade Econômica])) -> 0.72064383 | F14: =VLOOKUP($A14,Base_dados!A:H,6,FALSE()) -> 0 | G14: =VLOOKUP($A14,Base_dados!$A$5:$H$103,7,FALSE()) -> 0 | H14: =(VLOOKUP(Tabela4[[#This Row],[CNAE]],Tabela1[],8,FALSE))/100 -> 0.6707 | I14: =(C14*Config_Indicadores!$G$4+D14*Config_Indicadores!$G$5+E14*Config_Indicadores!$G$6+F14*Config_Indicadores!$G$7+G14*Config_Indicadores!$G$7+H14*Config_Indicadores!$G$8)/Config_Indicadores!$G$11 -> 0.25918773 | J14: =RANK(I14,Tabela4[Score Final],0) -> 25 | K14: =VLOOKUP(Tabela4[[#This Row],[CNAE]],Síntese2!A:G,6,FALSE) -> 2 | L14: =VLOOKUP(Tabela4[[#This Row],[CNAE]],Síntese2!A:G,3,FALSE) -> 59741332 | M14: =IF(Tabela4[[#This Row],[Tx Variação]]>=MEDIAN(Tabela4[Tx Variação]), "Alto","Baixo") -> Alto | N14: =IF(Tabela4[[#This Row],[Volume compra 2025]]>=MEDIAN(Tabela4[Volume compra 2025]), "Alto","Baixo") -> Alto | O14: =IF(AND(Tabela4[[#This Row],[Class Tx]]="Alto",Tabela4[[#This Row],[Class Volume]]="Alto"),"Estratégico",IF(AND(Tabela4[[#This Row],[Class Tx]]="Alto",Tabela4[[#This Row],[Class Volume]]="Baixo"),"Alavancagem",IF(AND(Tabela4[[#This Row],[Class Tx]]="Baixo",Tabela4[[#This Row],[Class Volume]]="Baixo"),"Não Crítico","Gargalo"))) -> Estratégico
A15: 310 | B15: Fabricação de móveis | C15: =(VLOOKUP($A15,Base_dados!$A$5:$H$103,3,FALSE())-MIN(Tabela1[IND01 Emprego]))/(MAX(Tabela1[IND01 Emprego])-MIN(Tabela1[IND01 Emprego])) -> 0.32244824 | D15: =(VLOOKUP($A15,Base_dados!$A$5:$H$103,4,FALSE())-MIN(Base_dados!C$5:C$103))/(MAX(Base_dados!C$5:C$103)-MIN(Base_dados!C$5:C$103)) -> 0.027614761 | E15: =(VLOOKUP($A15,Base_dados!$A$5:$H$103,5,FALSE())-MIN(Tabela1[IND03 Complexidade Econômica]))/(MAX(Tabela1[IND03 Complexidade Econômica])-MIN(Tabela1[IND03 Complexidade Econômica])) -> 0.37877477 | F15: =VLOOKUP($A15,Base_dados!A:H,6,FALSE()) -> 0 | G15: =VLOOKUP($A15,Base_dados!$A$5:$H$103,7,FALSE()) -> 0 | H15: =(VLOOKUP(Tabela4[[#This Row],[CNAE]],Tabela1[],8,FALSE))/100 -> 0.6028 | I15: =(C15*Config_Indicadores!$G$4+D15*Config_Indicadores!$G$5+E15*Config_Indicadores!$G$6+F15*Config_Indicadores!$G$7+G15*Config_Indicadores!$G$7+H15*Config_Indicadores!$G$8)/Config_Indicadores!$G$11 -> 0.236298 | J15: =RANK(I15,Tabela4[Score Final],0) -> 36 | K15: =VLOOKUP(Tabela4[[#This Row],[CNAE]],Síntese2!A:G,6,FALSE) -> -59.49 | L15: =VLOOKUP(Tabela4[[#This Row],[CNAE]],Síntese2!A:G,3,FALSE) -> 56658472 | M15: =IF(Tabela4[[#This Row],[Tx Variação]]>=MEDIAN(Tabela4[Tx Variação]), "Alto","Baixo") -> Baixo | N15: =IF(Tabela4[[#This Row],[Volume compra 2025]]>=MEDIAN(Tabela4[Volume compra 2025]), "Alto","Baixo") -> Alto | O15: =IF(AND(Tabela4[[#This Row],[Class Tx]]="Alto",Tabela4[[#This Row],[Class Volume]]="Alto"),"Estratégico",IF(AND(Tabela4[[#This Row],[Class Tx]]="Alto",Tabela4[[#This Row],[Class Volume]]="Baixo"),"Alavancagem",IF(AND(Tabela4[[#This Row],[Class Tx]]="Baixo",Tabela4[[#This Row],[Class Volume]]="Baixo"),"Não Crítico","Gargalo"))) -> Gargalo
A16: 329 | B16: Fabricação de produtos diversos | C16: =(VLOOKUP($A16,Base_dados!$A$5:$H$103,3,FALSE())-MIN(Tabela1[IND01 Emprego]))/(MAX(Tabela1[IND01 Emprego])-MIN(Tabela1[IND01 Emprego])) -> 0.075139514 | D16: =(VLOOKUP($A16,Base_dados!$A$5:$H$103,4,FALSE())-MIN(Base_dados!C$5:C$103))/(MAX(Base_dados!C$5:C$103)-MIN(Base_dados!C$5:C$103)) -> 0.014149415 | E16: =(VLOOKUP($A16,Base_dados!$A$5:$H$103,5,FALSE())-MIN(Tabela1[IND03 Complexidade Econômica]))/(MAX(Tabela1[IND03 Complexidade Econômica])-MIN(Tabela1[IND03 Complexidade Econômica])) -> 0.45403316 | F16: =VLOOKUP($A16,Base_dados!A:H,6,FALSE()) -> 0 | G16: =VLOOKUP($A16,Base_dados!$A$5:$H$103,7,FALSE()) -> 0 | H16: =(VLOOKUP(Tabela4[[#This Row],[CNAE]],Tabela1[],8,FALSE))/100 -> 0.8284 | I16: =(C16*Config_Indicadores!$G$4+D16*Config_Indicadores!$G$5+E16*Config_Indicadores!$G$6+F16*Config_Indicadores!$G$7+G16*Config_Indicadores!$G$7+H16*Config_Indicadores!$G$8)/Config_Indicadores!$G$11 -> 0.20669452 | J16: =RANK(I16,Tabela4[Score Final],0) -> 47 | K16: =VLOOKUP(Tabela4[[#This Row],[CNAE]],Síntese2!A:G,6,FALSE) -> 94.2 | L16: =VLOOKUP(Tabela4[[#This Row],[CNAE]],Síntese2!A:G,3,FALSE) -> 47127335 | M16: =IF(Tabela4[[#This Row],[Tx Variação]]>=MEDIAN(Tabela4[Tx Variação]), "Alto","Baixo") -> Alto | N16: =IF(Tabela4[[#This Row],[Volume compra 2025]]>=MEDIAN(Tabela4[Volume compra 2025]), "Alto","Baixo") -> Alto | O16: =IF(AND(Tabela4[[#This Row],[Class Tx]]="Alto",Tabela4[[#This Row],[Class Volume]]="Alto"),"Estratégico",IF(AND(Tabela4[[#This Row],[Class Tx]]="Alto",Tabela4[[#This Row],[Class Volume]]="Baixo"),"Alavancagem",IF(AND(Tabela4[[#This Row],[Class Tx]]="Baixo",Tabela4[[#This Row],[Class Volume]]="Baixo"),"Não Crítico","Gargalo"))) -> Estratégico
... A86: 111 | B86: Fabricação de bebidas alcoólicas | C86: =(VLOOKUP($A86,Base_dados!$A$5:$H$103,3,FALSE())-MIN(Tabela1[IND01 Emprego]))/(MAX(Tabela1[IND01 Emprego])-MIN(Tabela1[IND01 Emprego])) -> 0.10682268 | D86: =(VLOOKUP($A86,Base_dados!$A$5:$H$103,4,FALSE())-MIN(Base_dados!C$5:C$103))/(MAX(Base_dados!C$5:C$103)-MIN(Base_dados!C$5:C$103)) -> 0.002340234 | E86: =(VLOOKUP($A86,Base_dados!$A$5:$H$103,5,FALSE())-MIN(Tabela1[IND03 Complexidade Econômica]))/(MAX(Tabela1[IND03 Complexidade Econômica])-MIN(Tabela1[IND03 Complexidade Econômica])) -> 0.28548345 | F86: =VLOOKUP($A86,Base_dados!A:H,6,FALSE()) -> 0 | G86: =VLOOKUP($A86,Base_dados!$A$5:$H$103,7,FALSE()) -> 0 | H86: =(VLOOKUP(Tabela4[[#This Row],[CNAE]],Tabela1[],8,FALSE))/100 -> 0 | I86: =(C86*Config_Indicadores!$G$4+D86*Config_Indicadores!$G$5+E86*Config_Indicadores!$G$6+F86*Config_Indicadores!$G$7+G86*Config_Indicadores!$G$7+H86*Config_Indicadores!$G$8)/Config_Indicadores!$G$11 -> 0.071638435 | J86: =RANK(I86,Tabela4[Score Final],0) -> 78 | K86: =VLOOKUP(Tabela4[[#This Row],[CNAE]],Síntese2!A:G,6,FALSE) -> -50.56 | L86: =VLOOKUP(Tabela4[[#This Row],[CNAE]],Síntese2!A:G,3,FALSE) -> 421.2 | M86: =IF(Tabela4[[#This Row],[Tx Variação]]>=MEDIAN(Tabela4[Tx Variação]), "Alto","Baixo") -> Baixo | N86: =IF(Tabela4[[#This Row],[Volume compra 2025]]>=MEDIAN(Tabela4[Volume compra 2025]), "Alto","Baixo") -> Baixo | O86: =IF(AND(Tabela4[[#This Row],[Class Tx]]="Alto",Tabela4[[#This Row],[Class Volume]]="Alto"),"Estratégico",IF(AND(Tabela4[[#This Row],[Class Tx]]="Alto",Tabela4[[#This Row],[Class Volume]]="Baixo"),"Alavancagem",IF(AND(Tabela4[[#This Row],[Class Tx]]="Baixo",Tabela4[[#This Row],[Class Volume]]="Baixo"),"Não Crítico","Gargalo"))) -> Não Crítico
A87: 301 | B87: Construção de embarcações | C87: =(VLOOKUP($A87,Base_dados!$A$5:$H$103,3,FALSE())-MIN(Tabela1[IND01 Emprego]))/(MAX(Tabela1[IND01 Emprego])-MIN(Tabela1[IND01 Emprego])) -> 0.03459946 | D87: =(VLOOKUP($A87,Base_dados!$A$5:$H$103,4,FALSE())-MIN(Base_dados!C$5:C$103))/(MAX(Base_dados!C$5:C$103)-MIN(Base_dados!C$5:C$103)) -> 0.00050405041 | E87: =(VLOOKUP($A87,Base_dados!$A$5:$H$103,5,FALSE())-MIN(Tabela1[IND03 Complexidade Econômica]))/(MAX(Tabela1[IND03 Complexidade Econômica])-MIN(Tabela1[IND03 Complexidade Econômica])) -> 0.53707742 | F87: =VLOOKUP($A87,Base_dados!A:H,6,FALSE()) -> 0 | G87: =VLOOKUP($A87,Base_dados!$A$5:$H$103,7,FALSE()) -> 0 | H87: =(VLOOKUP(Tabela4[[#This Row],[CNAE]],Tabela1[],8,FALSE))/100 -> 0.9852 | I87: =(C87*Config_Indicadores!$G$4+D87*Config_Indicadores!$G$5+E87*Config_Indicadores!$G$6+F87*Config_Indicadores!$G$7+G87*Config_Indicadores!$G$7+H87*Config_Indicadores!$G$8)/Config_Indicadores!$G$11 -> 0.22742577 | J87: =RANK(I87,Tabela4[Score Final],0) -> 39 | K87: 0 | L87: 0 | M87: =IF(Tabela4[[#This Row],[Tx Variação]]>=MEDIAN(Tabela4[Tx Variação]), "Alto","Baixo") -> Baixo | N87: =IF(Tabela4[[#This Row],[Volume compra 2025]]>=MEDIAN(Tabela4[Volume compra 2025]), "Alto","Baixo") -> Baixo | O87: =IF(AND(Tabela4[[#This Row],[Class Tx]]="Alto",Tabela4[[#This Row],[Class Volume]]="Alto"),"Estratégico",IF(AND(Tabela4[[#This Row],[Class Tx]]="Alto",Tabela4[[#This Row],[Class Volume]]="Baixo"),"Alavancagem",IF(AND(Tabela4[[#This Row],[Class Tx]]="Baixo",Tabela4[[#This Row],[Class Volume]]="Baixo"),"Não Crítico","Gargalo"))) -> Não Crítico

Sheet Síntese2
A1: CNAE_GRUPO | B1: DESCRICAO_CNAE_GRUPO | C1: VALOR_TOTAL | D1: PART(%) | E1: VARIACAO_ABS | F1: VARIACAO(%) | G1: DEP_EXTERNA(%) | H1: ANO
A2: 014 | B2: Produção de sementes e mudas certificadas | C2: 409363.06 | D2: 0.01 | E2: 15380.7 | F2: 3.9 | G2: 0 | H2: 2025
A3: 015 | B3: Pecuária | C3: 49500 | D3: 0 | E3: 49500 | G3: 0 | H3: 2025
A4: 089 | B4: Extração de outros minerais não-metálicos | C4: 242000 | D4: 0.01 | E4: 242000 | G4: 100 | H4: 2025
A5: 101 | B5: Abate e fabricação de produtos de carne | C5: 2314737.2 | D5: 0.07 | E5: 29435.28 | F5: 1.29 | G5: 0 | H5: 2025
A6: 103 | B6: Fabricação de conservas de frutas, legumes e outros vegetais | C6: 1555329.2 | D6: 0.05 | E6: -6589.8 | F6: -0.42 | G6: 0 | H6: 2025
A7: 104 | B7: Fabricação de óleos e gorduras vegetais e animais | C7: 97408.3 | D7: 0 | E7: -4629.48 | F7: -4.54 | G7: 0 | H7: 2025
A8: 105 | B8: Laticínios | C8: 2251589.4 | D8: 0.07 | E8: 372025.31 | F8: 19.79 | G8: 0.41 | H8: 2025
A9: 106 | B9: Moagem, fabricação de produtos amiláceos e de alimentos para animais | C9: 44621710 | D9: 1.44 | E9: 30045066 | F9: 206.12 | G9: 1.29 | H9: 2025
A10: 107 | B10: Fabricação e refino de açúcar | C10: 596417.7 | D10: 0.02 | E10: -220878.83 | F10: -27.03 | G10: 0 | H10: 2025
A11: 109 | B11: Fabricação de outros produtos alimentícios | C11: 17578313 | D11: 0.57 | E11: 4993525.5 | F11: 39.68 | G11: 48.06 | H11: 2025
A12: 111 | B12: Fabricação de bebidas alcoólicas | C12: 421.2 | D12: 0 | E12: -430.72 | F12: -50.56 | G12: 0 | H12: 2025
A13: 112 | B13: Fabricação de bebidas não-alcoólicas | C13: 8187866.5 | D13: 0.26 | E13: 1175732.6 | F13: 16.77 | G13: 2.07 | H13: 2025
A14: 131 | B14: Preparação e fiação de fibras têxteis | C14: 23622.54 | D14: 0 | E14: -187949.94 | F14: -88.83 | G14: 0 | H14: 2025
A15: 132 | B15: Tecelagem, exceto malha | C15: 529450.57 | D15: 0.02 | E15: -338965.59 | F15: -39.03 | G15: 0 | H15: 2025
A16: 135 | B16: Fabricação de artefatos têxteis, exceto vestuário | C16: 11890405 | D16: 0.38 | E16: 5633014.6 | F16: 90.02 | G16: 76.3 | H16: 2025
... A27: 181 | B27: Atividade de impressão | C27: 5055711.3 | D27: 0.16 | E27: -1148257.7 | F27: -18.51 | G27: 7.25 | H27: 2025
A28: 183 | B28: Reprodução de materiais gravados em qualquer suporte | C28: 58016.65 | D28: 0 | E28: 58016.65 | G28: 0 | H28: 2025
A29: 192 | B29: Fabricação de produtos derivados do petróleo | C29: 4020034.7 | D29: 0.13 | E29: -1964771.9 | F29: -32.83 | G29: 49.99 | H29: 2025
A30: 201 | B30: Construção de embarcações | C30: 5013861.3 | D30: 0.16 | E30: 4933261.3 | F30: 6120.67 | G30: 98.52 | H30: 2025
A31: 201 | B31: Fabricação de produtos químicos inorgânicos | C31: 1678492.3 | D31: 0.05 | E31: 151179.23 | F31: 9.9 | G31: 0 | H31: 2025
A32: 205 | B32: Fabricação de defensivos agrícolas e desinfestantes domissanitários | C32: 1463796.4 | D32: 0.05 | E32: -1367674.7 | F32: -48.3 | G32: 1.15 | H32: 2025
A33: 206 | B33: Fabricação de sabões, detergentes, produtos de limpeza, cosméticos, produtos de perfumaria e de higiene pessoal | C33: 12163366 | D33: 0.39 | E33: -5754879.3 | F33: -32.12 | G33: 1.79 | H33: 2025
A34: 207 | B34: Fabricação de tintas, vernizes, esmaltes, lacas e produtos afins | C34: 1209169.7 | D34: 0.04 | E34: -1751334.6 | F34: -59.16 | G34: 0.7 | H34: 2025
A35: 209 | B35: Fabricação de produtos e preparados químicos diversos | C35: 7770695.4 | D35: 0.25 | E35: -3118258.1 | F35: -28.64 | G35: 47.88 | H35: 2025
A36: 211 | B36: Fabricação de produtos farmoquímicos | C36: 77553396 | D36: 2.51 | E36: 14880901 | F36: 23.74 | G36: 60.76 | H36: 2025
A37: 212 | B37: Fabricação de produtos farmacêuticos | C37: 8.8607514e+08 | D37: 28.65 | E37: 2.9805216e+08 | F37: 50.69 | G37: 79.42 | H37: 2025
A38: 221 | B38: Fabricação de produtos de borracha | C38: 5892364.5 | D38: 0.19 | E38: 660229.88 | F38: 12.62 | G38: 31.88 | H38: 2025
A39: 222 | B39: Fabricação de produtos de material plástico | C39: 31694553 | D39: 1.02 | E39: 16628971 | F39: 110.38 | G39: 2.1 | H39: 2025
A40: 231 | B40: Fabricação de vidro e de produtos do vidro | C40: 943828.49 | D40: 0.03 | E40: -699007.31 | F40: -42.55 | G40: 1.06 | H40: 2025
... A58: 267 | B58: Fabricação de equipamentos e instrumentos ópticos, fotográficos e cinematográficos | C58: 2344963.4 | D58: 0.08 | E58: -5735326.7 | F58: -70.98 | G58: 54.08 | H58: 2025
A59: 268 | B59: Fabricação de mídias virgens, magnéticas e ópticas | C59: 1093.66 | D59: 0 | E59: 1093.66 | G59: 0 | H59: 2025
A60: 271 | B60: Fabricação de geradores, transformadores e motores elétricos | C60: 3766643.9 | D60: 0.12 | E60: -74463.82 | F60: -1.94 | G60: 95.93 | H60: 2025
A61: 272 | B61: Fabricação de pilhas, baterias e acumuladores elétricos | C61: 999605.98 | D61: 0.03 | E61: 14502.12 | F61: 1.47 | G61: 11.95 | H61: 2025
A62: 273 | B62: Fabricação de equipamentos para distribuição e controle de energia elétrica | C62: 18239438 | D62: 0.59 | E62: 11962491 | F62: 190.58 | G62: 64.93 | H62: 2025
A63: 274 | B63: Fabricação de lâmpadas e outros equipamentos de iluminação | C63: 1394296.2 | D63: 0.05 | E63: -172555.4 | F63: -11.01 | G63: 28.09 | H63: 2025
A64: 275 | B64: Fabricação de eletrodomésticos | C64: 59741332 | D64: 1.93 | E64: 1168715.7 | F64: 2 | G64: 67.07 | H64: 2025
A65: 279 | B65: Fabricação de equipamentos e aparelhos elétricos não especificados anteriormente | C65: 1342163.5 | D65: 0.04 | E65: 593559.19 | F65: 79.29 | G65: 0.33 | H65: 2025
A66: 281 | B66: Fabricação de motores, bombas, compressores e equipamentos de transmissão | C66: 2547808 | D66: 0.08 | E66: -484807.13 | F66: -15.99 | G66: 76.34 | H66: 2025
A67: 282 | B67: Fabricação de máquinas e equipamentos de uso geral | C67: 30452440 | D67: 0.98 | E67: -4379159.4 | F67: -12.57 | G67: 81.05 | H67: 2025
...

Sheet Compras_CNAE
A1: CNAE_GRUPO | B1: DESCRICAO_CNAE_GRUPO | C1: 2023 | D1: 2025 | E1: PART_2023(%) | F1: PART_2025(%) | H1: CNAE_GRUPO | I1: DESCRICAO_CNAE_GRUPO | J1: 2025 | K1: PART_2025(%)
A2: 014 | B2: Produção de sementes e mudas certificadas | C2: 393982.36 | D2: 409363.06 | E2: 0.02 | F2: 0.01 | I2: Demais itens | K2: =100-K14 -> 20.48
A3: 015 | B3: Pecuária | C3: 0 | D3: 49500 | E3: 0 | F3: 0 | H3: 27.5 | I3: Eletrodomésticos | J3: 59741332 | K3: 1.93
A4: 089 | B4: Extração de outros minerais não-metálicos | C4: 0 | D4: 242000 | E4: 0 | F4: 0.01 | H4: 14.1 | I4: Artigos do vestuário e acessórios | J4: 65230981 | K4: 2.11
A5: 101 | B5: Abate e fabricação de produtos de carne | C5: 2285301.9 | D5: 2314737.2 | E5: 0.1 | F5: 0.07 | H5: 21.1 | I5: Produtos farmoquímicos | J5: 77553396 | K5: 2.51
A6: 103 | B6: Fabricação de conservas de frutas, legumes e outros vegetais | C6: 1561919 | D6: 1555329.2 | E6: 0.07 | F6: 0.05 | H6: 29.2 | I6: Caminhões e ônibus | J6: 100210843 | K6: 3.24
A7: 104 | B7: Fabricação de óleos e gorduras vegetais e animais | C7: 102037.78 | D7: 97408.3 | E7: 0 | F7: 0 | H7: 30.4 | I7: Aeronaves | J7: 1.0857182e+08 | K7: 3.51
A8: 105 | B8: Laticínios | C8: 1879564.1 | D8: 2251589.4 | E8: 0.08 | F8: 0.07 | H8: 28.3 | I8: Tratores e de máquinas e equipamentos para a agricultura e pecuária | J8: 1.2169332e+08 | K8: 3.94
A9: 106 | B9: Moagem, fabricação de produtos amiláceos e de alimentos para animais | C9: 14576644 | D9: 44621710 | E9: 0.65 | F9: 1.44 | H9: 26.2 | I9: Equipamentos de informática e periféricos | J9: 1.6621647e+08 | K9: 5.38
A10: 107 | B10: Fabricação e refino de açúcar | C10: 817296.53 | D10: 596417.7 | E10: 0.04 | F10: 0.02 | H10: 32.5 | I10: Instrumentos e materiais para uso médico e odontológico | J10: 3.6724693e+08 | K10: 11.88
A11: 109 | B11: Fabricação de outros produtos alimentícios | C11: 12584787 | D11: 17578313 | E11: 0.56 | F11: 0.57 | H11: 29.1 | I11: Automóveis, camionetas e utilitários | J11: 5.0631582e+08 | K11: 16.37
A12: 111 | B12: Fabricação de bebidas alcoólicas | C12: 851.92 | D12: 421.2 | E12: 0 | F12: 0 | H12: 21.2 | I12: Produtos farmacêuticos | J12: 8.8607514e+08 | K12: 28.65
A13: 112 | B13: Fabricação de bebidas não-alcoólicas | C13: 7012133.8 | D13: 8187866.5 | E13: 0.31 | F13: 0.26
A14: 131 | B14: Preparação e fiação de fibras têxteis | C14: 211572.48 | D14: 23622.54 | E14: 0.01 | F14: 0 | I14: TOTAL | J14: =SUM(J3:J12) -> 2.458856e+09 | K14: =SUM(K3:K12) -> 79.52
A15: 132 | B15: Tecelagem, exceto malha | C15: 868416.16 | D15: 529450.57 | E15: 0.04 | F15: 0.02
A16: 135 | B16: Fabricação de artefatos têxteis, exceto vestuário | C16: 6257390.7 | D16: 11890405 | E16: 0.28 | F16: 0.38 | H16: CNAE_GRUPO | I16: DESCRICAO_CNAE_GRUPO | J16: 2023 | K16: PART_2023(%)
A17: 141 | B17: Confecção de artigos do vestuário e acessórios | C17: 54537038 | D17: 65230981 | E17: 2.42 | F17: 2.11 | I17: Demais itens | K17: =100-K27 -> 20.42
A18: 142 | B18: Confecção de artigos do vestuário e acessórios | C18: 26212385 | D18: 33572509 | E18: 1.16 | F18: 1.09 | H18: 27.5 | I18: Eletrodomésticos | J18: 58572616 | K18: 2.6
A19: 152 | B19: Fabricação de artigos de malharia e tricotagem | C19: 671419.35 | D19: 47212.26 | E19: 0.03 | F19: 0 | H19: 21.1 | I19: Produtos farmoquímicos | J19: 62672495 | K19: 2.78
A20: 153 | B20: Fabricação de artigos para viagem e de artefatos diversos de couro | C20: 337704.95 | D20: 718210.54 | E20: 0.01 | F20: 0.02 | H20: 28.3 | I20: Tratores e de máquinas e equipamentos para a agricultura e pecuária | J20: 85267587 | K20: 3.79
A21: 161 | B21: Fabricação de calçados | C21: 1865335.2 | D21: 1083679.4 | E21: 0.08 | F21: 0.04 | H21: 26.2 | I21: Equipamentos de informática e periféricos | J21: 1.2471569e+08 | K21: 5.54
A22: 162 | B22: Desdobramento de madeira | C22: 359334.66 | D22: 243922.46 | E22: 0.02 | F22: 0.01 | H22: 26.5 | I22: Aparelhos e instrumentos de medida, teste e controle; cronômetros e relógios | J22: 1.3310276e+08 | K22: 5.91
A23: 172 | B23: Fabricação de produtos de madeira, cortiça e material trançado, exceto móveis | C23: 1295271.9 | D23: 1021084.1 | E23: 0.06 | F23: 0.03 | H23: 31.0 | I23: Móveis | J23: 1.3984907e+08 | K23: 6.21
A24: 173 | B24: Fabricação de papel, cartolina e papel-cartão | C24: 9200395.7 | D24: 9123023.9 | E24: 0.41 | F24: 0.3 | H24: 29.1 | I24: Automóveis, camionetas e utilitários | J24: 2.1646792e+08 | K24: 9.61
A25: 174 | B25: Fabricação de embalagens de papel, cartolina, papel-cartão e papelão ondulado | C25: 2334637.3 | D25: 2104914.7 | E25: 0.1 | F25: 0.07 | H25: 32.5 | I25: Instrumentos e materiais para uso médico e odontológico e de artigos ópticos | J25: 3.8349795e+08 | K25: 17.03
A26: 181 | B26: Fabricação de produtos diversos de papel, cartolina, papel-cartão e papelão ondulado | C26: 24478971 | D26: 20660760 | E26: 1.09 | F26: 0.67 | H26: 21.2 | I26: Produtos farmacêuticos | J26: 5.8802297e+08 | K26: 26.11
A27: 183 | B27: Atividade de impressão | C27: 6203969 | D27: 5055711.3 | E27: 0.28 | F27: 0.16 | I27: TOTAL | J27: =SUM(J18:J26) -> 1.7921691e+09 | K27: =SUM(K18:K26) -> 79.58
A28: 192 | B28: Reprodução de materiais gravados em qualquer suporte | C28: 0 | D28: 58016.65 | E28: 0 | F28: 0
A29: 201 | B29: Fabricação de produtos derivados do petróleo | C29: 5984806.6 | D29: 4020034.7 | E29: 0.27 | F29: 0.13
A30: 205 | B30: Fabricação de produtos químicos inorgânicos | C30: 1527313 | D30: 1678492.3 | E30: 0.07 | F30: 0.05
A31: 206 | B31: Fabricação de defensivos agrícolas e desinfestantes domissanitários | C31: 2831471.2 | D31: 1463796.4 | E31: 0.13 | F31: 0.05
A32: 207 | B32: Fabricação de sabões, detergentes, produtos de limpeza, cosméticos, produtos de perfumaria e de higiene pessoal | C32: 17918245 | D32: 12163366 | E32: 0.8 | F32: 0.39
A33: 209 | B33: Fabricação de tintas, vernizes, esmaltes, lacas e produtos afins | C33: 2960504.3 | D33: 1209169.7 | E33: 0.13 | F33: 0.04
A34: 211 | B34: Fabricação de produtos e preparados químicos diversos | C34: 10888954 | D34: 7770695.4 | E34: 0.48 | F34: 0.25
A35: 212 | B35: Fabricação de produtos farmoquímicos | C35: 62672495 | D35: 77553396 | E35: 2.78 | F35: 2.51
A36: 221 | B36: Fabricação de produtos farmacêuticos | C36: 5.8802297e+08 | D36: 8.8607514e+08 | E36: 26.11 | F36: 28.65
A37: 222 | B37: Fabricação de produtos de borracha | C37: 5232134.6 | D37: 5892364.5 | E37: 0.23 | F37: 0.19
A38: 231 | B38: Fabricação de produtos de material plástico | C38: 15065582 | D38: 31694553 | E38: 0.67 | F38: 1.02
A39: 232 | B39: Fabricação de vidro e de produtos do vidro | C39: 1642835.8 | D39: 943828.49 | E39: 0.07 | F39: 0.03
... A84: 620 | B84: Edição de livros, jornais, revistas e outras atividades de edição | C84: 8731445.5 | D84: 15966653 | E84: 0.39 | F84: 0.52
...

Sheet Dependencia_CNAE
A1: CNAE_GRUPO | B1: DESCRICAO_CNAE_GRUPO | C1: ANO | D1: Externo | E1: Local | F1: TOTAL | G1: DEP_EXTERNA(%)
A2: 014 | B2: Produção de sementes e mudas certificadas | C2: 2025 | D2: 0 | E2: 409363.06 | F2: 409363.06 | G2: 0
A3: 015 | B3: Pecuária | C3: 2025 | D3: 0 | E3: 49500 | F3: 49500 | G3: 0
A4: 089 | B4: Extração de outros minerais não-metálicos | C4: 2025 | D4: 242000 | E4: 0 | F4: 242000 | G4: 100
A5: 101 | B5: Abate e fabricação de produtos de carne | C5: 2025 | D5: 0 | E5: 2314737.2 | F5: 2314737.2 | G5: 0
A6: 103 | B6: Fabricação de conservas de frutas, legumes e outros vegetais | C6: 2025 | D6: 0 | E6: 1555329.2 | F6: 1555329.2 | G6: 0
A7: 104 | B7: Fabricação de óleos e gorduras vegetais e animais | C7: 2025 | D7: 0 | E7: 97408.3 | F7: 97408.3 | G7: 0
A8: 105 | B8: Laticínios | C8: 2025 | D8: 9274.67 | E8: 2242314.8 | F8: 2251589.4 | G8: 0.41
A9: 106 | B9: Moagem, fabricação de produtos amiláceos e de alimentos para animais | C9: 2025 | D9: 573691.99 | E9: 44048018 | F9: 44621710 | G9: 1.29
A10: 107 | B10: Fabricação e refino de açúcar | C10: 2025 | D10: 0 | E10: 596417.7 | F10: 596417.7 | G10: 0
A11: 109 | B11: Fabricação de outros produtos alimentícios | C11: 2025 | D11: 8448880.8 | E11: 9129431.8 | F11: 17578313 | G11: 48.06
A12: 111 | B12: Fabricação de bebidas alcoólicas | C12: 2025 | D12: 0 | E12: 421.2 | F12: 421.2 | G12: 0
A13: 112 | B13: Fabricação de bebidas não-alcoólicas | C13: 2025 | D13: 169300.29 | E13: 8018566.2 | F13: 8187866.5 | G13: 2.07
... A16: 135 | B16: Fabricação de artefatos têxteis, exceto vestuário | C16: 2025 | D16: 9072382 | E16: 2818023.3 | F16: 11890405 | G16: 76.3
A17: 141 | B17: Confecção de artigos do vestuário e acessórios | C17: 2025 | D17: 17971825 | E17: 80831665 | F17: 98803490 | G17: 28.84
A18: 142 | B18: Fabricação de artigos de malharia e tricotagem | C18: 2025 | D18: 32750 | E18: 14462.26 | F18: 47212.26 | G18: 69.37
A19: 152 | B19: Fabricação de artigos para viagem e de artefatos diversos de couro | C19: 2025 | D19: 538192.22 | E19: 180018.32 | F19: 718210.54 | G19: 74.94
A20: 153 | B20: Fabricação de calçados | C20: 2025 | D20: 864817 | E20: 218862.45 | F20: 1083679.4 | G20: 79.8
A21: 161 | B21: Desdobramento de madeira | C21: 2025 | D21: 22117.95 | E21: 221804.51 | F21: 243922.46 | G21: 9.07
A22: 162 | B22: Fabricação de produtos de madeira, cortiça e material trançado, exceto móveis | C22: 2025 | D22: 0 | E22: 1021084.1 | F22: 1021084.1 | G22: 0
A23: 172 | B23: Fabricação de papel, cartolina e papel-cartão | C23: 2025 | D23: 5008354.1 | E23: 4114669.8 | F23: 9123023.9 | G23: 54.9
A24: 173 | B24: Fabricação de embalagens de papel, cartolina, papel-cartão e papelão ondulado | C24: 2025 | D24: 949348.19 | E24: 1155566.5 | F24: 2104914.7 | G24: 45.1
A25: 174 | B25: Fabricação de produtos diversos de papel, cartolina, papel-cartão e papelão ondulado | C25: 2025 | D25: 351207.3 | E25: 20309553 | F25: 20660760 | G25: 1.7
A26: 181 | B26: Atividade de impressão | C26: 2025 | D26: 366303.2 | E26: 4689408.1 | F26: 5055711.3 | G26: 7.25
A27: 183 | B27: Reprodução de materiais gravados em qualquer suporte | C27: 2025 | D27: 0 | E27: 58016.65 | F27: 58016.65 | G27: 0
A28: 192 | B28: Fabricação de produtos derivados do petróleo | C28: 2025 | D28: 2009573.6 | E28: 2010461.1 | F28: 4020034.7 | G28: 49.99
A29: 201 | B29: Fabricação de produtos químicos inorgânicos | C29: 2025 | D29: 0 | E29: 1678492.3 | F29: 1678492.3 | G29: 0
... A84: 620 | B84: Atividades dos serviços de tecnologia da informação | C84: 2025 | D84: 1718444.6 | E84: 14682503 | F84: 16400948 | G84: 10.48

Sheet RAIS Vínculos - Bahia 2023-2025
A1: Cod. | B1: CNAE 2.0 Grupo - BAHIA | C1: 2025 | D1: 2024 | E1: 2.023 | F1: Total
A2: 060 | B2: Extração de petróleo e gás natural | C2: 3.209 | D2: 3.028 | E2: 2526 | F2: 8.763
A3: 071 | B3: Extração de minério de ferro | C3: 288 | D3: 316 | E3: 374 | F3: 978
A4: 072 | B4: Extração de minerais metálicos não-ferrosos | C4: 8.106 | D4: 7.989 | E4: 7987 | F4: 24.082
A5: 081 | B5: Extração de pedra, areia e argila | C5: 4.843 | D5: 4.621 | E5: 4166 | F5: 13.630
A6: 089 | B6: Extração de outros minerais não-metálicos | C6: 2.526 | D6: 2.331 | E6: 2149 | F6: 7.006
A7: 091 | B7: Atividades de apoio à extração de petróleo e gás natural | C7: 2.480 | D7: 2.669 | E7: 2786 | F7: 7.935
A8: 099 | B8: Atividades de apoio à extração de minerais, exceto petróleo e gás natural | C8: 257 | D8: 329 | E8: 368 | F8: 954
A9: 101 | B9: Abate e fabricação de produtos de carne | C9: 13.690 | D9: 12.594 | E9: 11278 | F9: 37.562
A10: 102 | B10: Preservação do pescado e fabricação de produtos do pescado | C10: 741 | D10: 727 | E10: 707 | F10: 2.175
A11: 103 | B11: Fabricação de conservas de frutas, legumes e outros vegetais | C11: 3.227 | D11: 3.068 | E11: 2909 | F11: 9.204
A12: 104 | B12: Fabricação de óleos e gorduras vegetais e animais | C12: 1.654 | D12: 1.636 | E12: 1540 | F12: 4.830
A13: 105 | B13: Laticínios | C13: 5.773 | D13: 5.509 | E13: 5176 | F13: 16.458
... A124: 439 | B124: Outros serviços especializados para construção | C124: 12.069 | D124: 11.314 | E124: 13224 | F124: 36.607
B125: Total | C125: 493.628 | D125: 469.070 | E125: 460646 | F125: 1.423.344
A126: 014 | B126: Produção de sementes e mudas certificadas | C126: 1795 | D126: 1724 | E126: 1551 | F126: 5070
A127: 015 | B127: Pecuária | C127: 27775 | D127: 27229 | E127: 26648 | F127: 81652
A128: 255 | B128: Fabricação de equipamento bélico pesado, armas de fogo e munições | C128: 0 | D128: 0 | E128: 0 | F128: 0
A129: 292 | B129: Fabricação de caminhões e ônibus | C129: 0 | D129: 0 | E129: 0 | F129: 0
A130: 581 | B130: Edição de livros, jornais, revistas e outras atividades de edição | C130: 164 | D130: 187 | E130: 149 | F130: 500
A131: 620 | B131: Atividades dos serviços de tecnologia da informação | C131: 11463 | D131: 10922 | E131: 10586 | F131: 32971

Sheet RAIS Estabelecimentos - Bah (2)
A1: Cod. | B1: CNAE 2.0 Grupo - BAHIA | C1: 2025 | D1: 2024 | E1: 2023 | F1: Total
A2: 014 | B2: Produção de Sementes e Mudas Certificadas | C2: 102 | D2: 96 | E2: 91 | F2: 289
A3: 015 | B3: Pecuária | C3: 8367 | D3: 8343 | E3: 8343 | F3: 25053
A4: 060 | B4: Extração de Petróleo e Gás Natural | C4: 19 | D4: 20 | E4: 23 | F4: 62
A5: 071 | B5: Extração de Minério de Ferro | C5: 10 | D5: 10 | E5: 10 | F5: 30
A6: 072 | B6: Extração de Minerais Metálicos Não-Ferrosos | C6: 35 | D6: 32 | E6: 35 | F6: 102
A7: 081 | B7: Extração de Pedra, Areia e Argila | C7: 406 | D7: 384 | E7: 358 | F7: 1.148
A8: 089 | B8: Extração de Outros Minerais Não-Metálicos | C8: 77 | D8: 72 | E8: 66 | F8: 215
A9: 091 | B9: Atividades de Apoio à Extração de Petróleo e Gás Natural | C9: 36 | D9: 35 | E9: 31 | F9: 102
A10: 099 | B10: Atividades de Apoio à Extração de Minerais, Exceto Petróleo e Gás Natural | C10: 19 | D10: 20 | E10: 20 | F10: 59
A11: 101 | B11: Abate e Fabricação de Produtos de Carne | C11: 140 | D11: 139 | E11: 133 | F11: 412
A12: 102 | B12: Preservação do Pescado e Fabricação de Produtos do Pescado | C12: 23 | D12: 24 | E12: 21 | F12: 68
A13: 103 | B13: Fabricação de Conservas de Frutas, Legumes e Outros Vegetais | C13: 220 | D13: 202 | E13: 196 | F13: 618
A14: 104 | B14: Fabricação de óleos e Gorduras Vegetais e Animais | C14: 37 | D14: 38 | E14: 37 | F14: 112
A15: 105 | B15: Laticínios | C15: 410 | D15: 387 | E15: 364 | F15: 1.161
... A126: 439 | B126: Outros Serviços Especializados para Construção | C126: 1.039 | D126: 974 | E126: 909 | F126: 2.922
B127: Total | C127: 25.184 | D127: 24.071 | E127: 22871 | F127: 72.126
A128: 255 | B128: Fabricação de equipamento bélico pesado, armas de fogo e munições | C128: 0 | D128: 0 | E128: 0
A129: 292 | B129: Fabricação de caminhões e ônibus | C129: 0 | D129: 0 | E129: 0
A130: 581 | B130: Edição de livros, jornais, revistas e outras atividades de edição | C130: 70 | D130: 70 | E130: 68 | F130: 208
A131: 620 | B131: Atividades dos serviços de tecnologia da informação | C131: 715 | D131: 688 | E131: 677 | F131: 2080

Sheet Complexidade
A1: grupo_cnae | B1: ubiquidade | C1: ubiquidade_share | D1: complexidade_grupo_cnae_ancorada | E1: ano
A2: 011 | B2: 1931 | C2: 0.34661641 | D2: -1.828616 | E2: 2025
A3: 012 | B3: 843 | C3: 0.34661641 | D3: -1.1378473 | E3: 2025
A4: 013 | B4: 1238 | C4: 0.34661641 | D4: -1.6935156 | E4: 2025
A5: 014 | B5: 511 | C5: 0.34661641 | D5: -1.0904121 | E5: 2025
A6: 015 | B6: 3131 | C6: 0.34661641 | D6: -1.8588591 | E6: 2025
A7: 016 | B7: 2787 | C7: 0.34661641 | D7: -1.783902 | E7: 2025
A8: 017 | B8: 17 | C8: 0.34661641 | D8: -0.61585865 | E8: 2025
A9: 021 | B9: 988 | C9: 0.34661641 | D9: -1.6348501 | E9: 2025
A10: 022 | B10: 350 | C10: 0.34661641 | D10: -1.6100658 | E10: 2025
A11: 023 | B11: 441 | C11: 0.34661641 | D11: -1.3575863 | E11: 2025
A12: 031 | B12: 147 | C12: 0.34661641 | D12: -0.86900117 | E12: 2025
A13: 032 | B13: 593 | C13: 0.34661641 | D13: -1.4291152 | E13: 2025
... A124: 332 | B124: 561 | C124: 0.34661641 | D124: 0.074340741 | E124: 2025
A125: 351 | B125: 833 | C125: 0.34661641 | D125: -1.107326 | E125: 2025
A126: 352 | B126: 52 | C126: 0.34661641 | D126: 1.2029104 | E126: 2025
A127: 353 | B127: 55 | C127: 0.34661641 | D127: 1.2512647 | E127: 2025
A128: 360 | B128: 1003 | C128: 0.34661641 | D128: -1.3191627 | E128: 2025
A129: 370 | B129: 229 | C129: 0.34661641 | D129: 0.22959559 | E129: 2025
A130: 381 | B130: 421 | C130: 0.34661641 | D130: -0.3924245 | E130: 2025
A131: 382 | B131: 266 | C131: 0.34661641 | D131: 0.22292853 | E131: 2025
A132: 383 | B132: 627 | C132: 0.34661641 | D132: 0.049597166 | E132: 2025
A133: 390 | B133: 48 | C133: 0.34661641 | D133: 1.1382792 | E133: 2025
A134: 411 | B134: 309 | C134: 0.34661641 | D134: 0.11065203 | E134: 2025
A135: 412 | B135: 1007 | C135: 0.34661641 | D135: -1.236015 | E135: 2025
A136: 421 | B136: 971 | C136: 0.34661641 | D136: -1.4231102 | E136: 2025
... A186: 562 | B186: 359 | C186: 0.34661641 | D186: 0.096154786 | E186: 2025
A187: 581 | B187: 189 | C187: 0.34661641 | D187: -0.1216345 | E187: 2025
A188: 582 | B188: 257 | C188: 0.34661641 | D188: 0.20981264 | E188: 2025
A189: 591 | B189: 195 | C189: 0.34661641 | D189: 0.2725661 | E189: 2025
A190: 592 | B190: 90 | C190: 0.34661641 | D190: 0.34339719 | E190: 2025
A191: 601 | B191: 1058 | C191: 0.34661641 | D191: -0.55503772 | E191: 2025
A192: 602 | B192: 92 | C192: 0.34661641 | D192: 0.81408452 | E192: 2025
A193: 611 | B193: 1773 | C193: 0.34661641 | D193: -1.7012389 | E193: 2025
A194: 612 | B194: 52 | C194: 0.34661641 | D194: 0.83312005 | E194: 2025
A195: 613 | B195: 27 | C195: 0.34661641 | D195: 0.88386879 | E195: 2025
A196: 614 | B196: 61 | C196: 0.34661641 | D196: -0.022657096 | E196: 2025
A197: 619 | B197: 1301 | C197: 0.34661641 | D197: -1.3056909 | E197: 2025
A198: 620 | B198: 170 | C198: 0.34661641 | D198: 0.099233406 | E198: 2025
A199: 631 | B199: 237 | C199: 0.34661641 | D199: -0.36457191 | E199: 2025
...

Sheet CNAE_TSB
A1: CNAE | B1: Setor | C1: TSB | D1: Evidência (caderno / atividade)
A2: 014 | B2: Produção de sementes e mudas certificadas | C2: 0
A3: 015 | B3: Pecuária | C3: 1 | D3: CNAE A - Apêndice A4: pecuária bovina de corte e leite a pasto (01.51-2/01, 01.51-2/02)
A4: 089 | B4: Extração de outros minerais não-metálicos | C4: 1 | D4: CNAE B - B8 Grafita (08.99-1/01) e B9 Quartzo (08.99-1/02)
A5: 101 | B5: Abate e fabricação de produtos de carne | C5: 0
A6: 103 | B6: Fabricação de conservas de frutas, legumes e outros vegetais | C6: 0
A7: 104 | B7: Fabricação de óleos e gorduras vegetais e animais | C7: 0
A8: 105 | B8: Laticínios | C8: 0
A9: 106 | B9: Moagem, fabricação de produtos amiláceos e de alimentos para animais | C9: 0
A10: 107 | B10: Fabricação e refino de açúcar | C10: 0
A11: 109 | B11: Fabricação de outros produtos alimentícios | C11: 0
A12: 111 | B12: Fabricação de bebidas alcoólicas | C12: 0
A13: 112 | B13: Fabricação de bebidas não-alcoólicas | C13: 0
A14: 131 | B14: Preparação e fiação de fibras têxteis | C14: 0
A15: 132 | B15: Tecelagem, exceto malha | C15: 0
A16: 135 | B16: Fabricação de artefatos têxteis, exceto vestuário | C16: 0
... A22: 162 | B22: Fabricação de produtos de madeira, cortiça e material trançado, exceto móveis | C22: 0
A23: 172 | B23: Fabricação de papel, cartolina e papel-cartão | C23: 1 | D23: CNAE C - C7 Papel e celulose (17.21-4, 17.22-2)
A24: 173 | B24: Fabricação de embalagens de papel, cartolina, papel-cartão e papelão ondulado | C24: 1 | D24: CNAE C - C7 Papel e celulose (17.31-1, 17.32-0, 17.33-8)
A25: 174 | B25: Fabricação de produtos diversos de papel, cartolina, papel-cartão e papelão ondulado | C25: 1 | D25: CNAE C - C7 Papel e celulose (17.41-9, 17.42-7, 17.49-4)
A26: 181 | B26: Atividade de impressão | C26: 0
A27: 183 | B27: Reprodução de materiais gravados em qualquer suporte | C27: 0
A28: 192 | B28: Fabricação de produtos derivados do petróleo | C28: 0
A29: 201 | B29: Fabricação de produtos químicos inorgânicos | C29: 1 | D29: CNAE C - C6 Químicos inorgânicos (20.11-8, 20.12-6, 20.14-2, 20.19-3/99)
A30: 205 | B30: Fabricação de defensivos agrícolas e desinfestantes domissanitários | C30: 0
A31: 206 | B31: Fabricação de sabões, detergentes, produtos de limpeza, cosméticos, produtos de perfumaria e de higiene pessoal | C31: 0
A32: 207 | B32: Fabricação de tintas, vernizes, esmaltes, lacas e produtos afins | C32: 0
A33: 209 | B33: Fabricação de produtos e preparados químicos diversos | C33: 1 | D33: CNAE C - C5 Aditivos de uso industrial (20.93-2)
A34: 211 | B34: Fabricação de produtos farmoquímicos | C34: 0
A35: 212 | B35: Fabricação de produtos farmacêuticos | C35: 0
